<?xml version="1.0" ?>
<sdf version="1.8">

        <model name='vehicle_blue' canonical_link='chassis'>
            <pose relative_to='world'>0 0 0 0 0 0</pose>   <!--the pose is relative to the world by default-->
            <link name='chassis'>
                <pose relative_to='__model__'>0.5 0 0.4 0 0 0</pose>
                <inertial> <!--inertial properties of the link mass, inertia matix-->
                    <mass>1.14395</mass>
                    <inertia>
                        <ixx>0.126164</ixx>
                        <ixy>0</ixy>
                        <ixz>0</ixz>
                        <iyy>0.416519</iyy>
                        <iyz>0</iyz>
                        <izz>0.481014</izz>
                    </inertia>
                </inertial>
                <visual name='visual'>
                    <geometry>
                        <box>
                            <size>0.6 0.4 0.1</size> <!--question: this size is in meter-->
                        </box>
                    </geometry>
                    <!--let's add color to our link-->
                    <material>
                        <ambient>1.0 0.0 0.0 1</ambient>
                        <diffuse>1.0 0.0 0.0 1</diffuse>
                        <specular>1.0 0.0 0.0 1</specular>
                    </material>
                </visual>
                <collision name='collision'> <!--todo: describe why we need the collision-->
                    <geometry>
                        <box>
                            <size>0.6 0.4 0.1</size>
                        </box>
                    </geometry>
                </collision>
            </link>


            <!--let's build the left wheel-->
            <link name='left_wheel_back'>
                <pose relative_to="chassis">-0.25 0.25 0.0 1.5707 0 0</pose> <!--angles are in radian-->
                <inertial>
                    <mass>2</mass>
                    <inertia>
                        <ixx>0.145833</ixx>
                        <ixy>0</ixy>
                        <ixz>0</ixz>
                        <iyy>0.145833</iyy>
                        <iyz>0</iyz>
                        <izz>0.125</izz>
                    </inertia>
                </inertial>
                <visual name='visual'>
                    <geometry>
                        <cylinder>
                            <radius>0.1</radius>
                            <length>0.1</length>
                        </cylinder>
                    </geometry>
                    <material>
                        <ambient>0 0 0 1</ambient>
                        <diffuse>0 0 0 1</diffuse>
                        <specular>0 0 0 1</specular>
                    </material>
                </visual>
                <collision name='collision'>
                    <geometry>
                        <cylinder>
                            <radius>0.1</radius>
                            <length>0.1</length>
                        </cylinder>
                    </geometry>
                </collision>
            </link>

            <link name='left_wheel_front'>
                <pose relative_to="chassis">0.25 0.25 0 1.5707 0 0</pose> <!--angles are in radian-->
                <inertial>
                    <mass>2</mass>
                    <inertia>
                        <ixx>0.145833</ixx>
                        <ixy>0</ixy>
                        <ixz>0</ixz>
                        <iyy>0.145833</iyy>
                        <iyz>0</iyz>
                        <izz>0.125</izz>
                    </inertia>
                </inertial>
                <visual name='visual'>
                    <geometry>
                        <cylinder>
                            <radius>0.1</radius>
                            <length>0.1</length>
                        </cylinder>
                    </geometry>
                    <material>
                        <ambient>0 0 0 1</ambient>
                        <diffuse>0 0 0 1</diffuse>
                        <specular>0 0 0 1</specular>
                    </material>
                </visual>
                <collision name='collision'>
                    <geometry>
                        <cylinder>
                            <radius>0.1</radius>
                            <length>0.1</length>
                        </cylinder>
                    </geometry>
                </collision>
            </link>

            <link name='right_wheel_back'>
                <pose relative_to="chassis">-0.25 -0.25 0 1.5707 0 0</pose> <!--angles are in radian-->
                <inertial>
                    <mass>2</mass>
                    <inertia>
                        <ixx>0.145833</ixx>
                        <ixy>0</ixy>
                        <ixz>0</ixz>
                        <iyy>0.145833</iyy>
                        <iyz>0</iyz>
                        <izz>0.125</izz>
                    </inertia>
                </inertial>
                <visual name='visual'>
                    <geometry>
                        <cylinder>
                            <radius>0.1</radius>
                            <length>0.1</length>
                        </cylinder>
                    </geometry>
                    <material>
                        <ambient>0 0 0 1</ambient>
                        <diffuse>0 0 0 1</diffuse>
                        <specular>0 0 0 1</specular>
                    </material>
                </visual>
                <collision name='collision'>
                    <geometry>
                        <cylinder>
                            <radius>0.1</radius>
                            <length>0.1</length>
                        </cylinder>
                    </geometry>
                </collision>
            </link>

            <link name='right_wheel_front'>
                <pose relative_to="chassis">0.25 -0.25 0 1.5707 0 0</pose> <!--angles are in radian-->
                <inertial>
                    <mass>2</mass>
                    <inertia>
                        <ixx>0.145833</ixx>
                        <ixy>0</ixy>
                        <ixz>0</ixz>
                        <iyy>0.145833</iyy>
                        <iyz>0</iyz>
                        <izz>0.125</izz>
                    </inertia>
                </inertial>
                <visual name='visual'>
                    <geometry>
                        <cylinder>
                            <radius>0.1</radius>
                            <length>0.1</length>
                        </cylinder>
                    </geometry>
                    <material>
                        <ambient>0 0 0 1</ambient>
                        <diffuse>0 0 0 1</diffuse>
                        <specular>0 0 0 1</specular>
                    </material>
                </visual>
                <collision name='collision'>
                    <geometry>
                        <cylinder>
                            <radius>0.1</radius>
                            <length>0.1</length>
                        </cylinder>
                    </geometry>
                </collision>
            </link>

            <!--connecting these links together using joints-->
            <joint name='left_wheel_back_joint' type='revolute'> <!--continous joint is not supported yet-->
                <pose relative_to='left_wheel_back'/>
                <parent>chassis</parent>
                <child>left_wheel_back</child>
                <axis>
                    <xyz expressed_in='__model__'>0 1 0</xyz> <!--can be defined as any frame or even arbitrary frames-->
                    <limit>
                        <lower>-1.79769e+308</lower>    <!--negative infinity-->
                        <upper>1.79769e+308</upper>     <!--positive infinity-->
                    </limit>
                </axis>
            </joint>

            <joint name='right_wheel_back_joint' type='revolute'>
                <pose relative_to='right_wheel_back'/>
                <parent>chassis</parent>
                <child>right_wheel_back</child>
                <axis>
                    <xyz expressed_in='__model__'>0 1 0</xyz>
                    <limit>
                        <lower>-1.79769e+308</lower>    <!--negative infinity-->
                        <upper>1.79769e+308</upper>     <!--positive infinity-->
                    </limit>
                </axis>
            </joint>

            <joint name='left_wheel_front_joint' type='revolute'> <!--continous joint is not supported yet-->
                <pose relative_to='left_wheel_front'/>
                <parent>chassis</parent>
                <child>left_wheel_front</child>
                <axis>
                    <xyz expressed_in='__model__'>0 1 0</xyz> <!--can be defined as any frame or even arbitrary frames-->
                    <limit>
                        <lower>-1.79769e+308</lower>    <!--negative infinity-->
                        <upper>1.79769e+308</upper>     <!--positive infinity-->
                    </limit>
                </axis>
            </joint>

            <joint name='right_wheel_front_joint' type='revolute'>
                <pose relative_to='right_wheel_front'/>
                <parent>chassis</parent>
                <child>right_wheel_front</child>
                <axis>
                    <xyz expressed_in='__model__'>0 1 0</xyz>
                    <limit>
                        <lower>-1.79769e+308</lower>    <!--negative infinity-->
                        <upper>1.79769e+308</upper>     <!--positive infinity-->
                    </limit>
                </axis>
            </joint>

            <link name='camera_module'>
                <pose relative_to='chassis'>-0.2 0 0.05  0 0 0</pose>
                <inertial> <!--inertial properties of the link mass, inertia matix-->
                    <mass>1.14395</mass>
                    <inertia>
                        <ixx>0.126164</ixx>
                        <ixy>0</ixy>
                        <ixz>0</ixz>
                        <iyy>0.416519</iyy>
                        <iyz>0</iyz>
                        <izz>0.481014</izz>
                    </inertia>
                </inertial>
                <visual name='visual'>
                    <geometry>
                        <box>
                            <size>0.1 0.1 0.05</size> <!--question: this size is in meter-->
                        </box>
                    </geometry>
                    <!--let's add color to our link-->
                    <material>
                        <ambient>1.0 1.0 0.0 1</ambient>
                        <diffuse>1.0 1.0 0.0 1</diffuse>
                        <specular>1.0 1.0 0.0 1</specular>
                    </material>
                </visual>
                <collision name='collision'> <!--todo: describe why we need the collision-->
                    <geometry>
                        <box>
                            <size>0.2 0.2 0.1</size>
                        </box>
                    </geometry>
                </collision>
            </link>

            <joint name='camera_module_joint' type='fixed'>
                <pose relative_to='chassis'/>
                <parent>chassis</parent>
                <child>camera_module</child>
            </joint>

            <link name='arm_base'>
                <pose relative_to='chassis'>0.2 0 0.1  0 0 0</pose>
                <inertial> <!--inertial properties of the link mass, inertia matix-->
                    <mass>1.14395</mass>
                    <inertia>
                        <ixx>0.126164</ixx>
                        <ixy>0</ixy>
                        <ixz>0</ixz>
                        <iyy>0.416519</iyy>
                        <iyz>0</iyz>
                        <izz>0.481014</izz>
                    </inertia>
                </inertial>
                <visual name='visual'>
                    <geometry>
                        <cylinder>
                            <radius>0.05</radius>
                            <length>0.1</length>
                        </cylinder>
                    </geometry>
                    <!--let's add color to our link-->
                    <material>
                        <ambient>0.0 0.0 1.0 1</ambient>
                        <diffuse>0.0 0.0 1.0 1</diffuse>
                        <specular>0.0 0.0 1.0 1</specular>
                    </material>
                </visual>
                <collision name='collision'> <!--todo: describe why we need the collision-->
                    <geometry>
                        <cylinder>
                            <radius>0.05</radius>
                            <length>0.1</length>
                        </cylinder>
                    </geometry>
                </collision>
            </link>

            <joint name='arm_base_joint' type='fixed'>
                <pose relative_to='chassis'/>
                <parent>chassis</parent>
                <child>arm_base</child>
            </joint>

            <link name='arm1'>
                <!-- <pose relative_to="arm_base">0.175 0 0.05 0 0 0</pose> -->
                <pose relative_to="arm_base">0.175 0 0.05 0 0 0</pose>
                <inertial>
                    <mass>2</mass>
                    <inertia>
                        <ixx>0.145833</ixx>
                        <ixy>0</ixy>
                        <ixz>0</ixz>
                        <iyy>0.145833</iyy>
                        <iyz>0</iyz>
                        <izz>0.125</izz>
                    </inertia>
                </inertial>
                <visual name='visual'>
                    <geometry>
                        <box>
                            <size>0.3 0.02 0.02</size>
                        </box>
                    </geometry>
                    <material>
                        <ambient>0 0 1 1</ambient>
                        <diffuse>0 0 1 1</diffuse>
                        <specular>0 0 1 1</specular>
                    </material>
                </visual>
                <collision name='collision'>
                    <geometry>
                        <box>
                            <size>0.3 0.02 0.02</size>
                        </box>
                    </geometry>
                </collision>
            </link>

            <joint name='arm1_joint' type='revolute'> 
                <pose relative_to="arm_base">0.025 0 0.05 0 0 0</pose>
                <parent>arm_base</parent>
                <child>arm1</child>
                <axis>
                    <xyz expressed_in='__model__'>0 1 0</xyz> 
                    <limit>
                        <lower>-1.57</lower>    
                        <upper>1.57</upper>
                    </limit>
                </axis>
            </joint>

            <link name='arm1_ball'>
                <pose relative_to="arm1">0.12 0 0.0 0 0 0</pose> <!--angles are in radian-->
                <inertial>
                    <mass>2</mass>
                    <inertia>
                        <ixx>0.145833</ixx>
                        <ixy>0</ixy>
                        <ixz>0</ixz>
                        <iyy>0.145833</iyy>
                        <iyz>0</iyz>
                        <izz>0.125</izz>
                    </inertia>
                </inertial>
                <visual name='visual'>
                    <geometry>
                        <sphere>
                            <radius>0.03</radius>
                        </sphere>
                    </geometry>
                    <material>
                        <ambient>0 0 0 1</ambient>
                        <diffuse>0 0 0 1</diffuse>
                        <specular>0 0 0 1</specular>
                    </material>
                </visual>
                <collision name='collision'>
                    <geometry>
                        <sphere>
                            <radius>0.01</radius>
                        </sphere>
                    </geometry>
                </collision>
            </link>

            <joint name='arm1_ball_joint' type='fixed'> 
                <pose relative_to='arm1'/>
                <parent>arm1</parent>
                <child>arm1_ball</child>
            </joint>


            <link name='arm2'>
                <pose relative_to="arm1">0.3 0 0 0 0 0</pose> <!--angles are in radian-->
                <inertial>
                    <mass>0</mass>
                    <inertia>
                        <ixx>0.145833</ixx>
                        <ixy>0</ixy>
                        <ixz>0</ixz>
                        <iyy>0.145833</iyy>
                        <iyz>0</iyz>
                        <izz>0.125</izz>
                    </inertia>
                </inertial>
                <visual name='visual'>
                    <geometry>
                        <box>
                            <size>0.3 0.02 0.02</size>
                        </box>
                    </geometry>
                    <material>
                        <ambient>0 0.5 0 1</ambient>
                        <diffuse>0 0.5 0 1</diffuse>
                        <specular>0 0.5 0 1</specular>
                    </material>
                </visual>
                <collision name='collision'>
                    <geometry>
                        <box>
                            <size>0.3 0.02 0.02</size>
                        </box>
                    </geometry>
                </collision>
            </link>

            <joint name='arm2_joint' type='revolute'> 
                <pose relative_to="arm1">0.15 0 0 0 0 0</pose>
                <parent>arm1</parent>
                <child>arm2</child>
                <axis>
                    <xyz expressed_in='__model__'>0 1 0</xyz> 
                    <limit>
                        <lower>-1.57</lower>    
                        <upper>1.57</upper>
                    </limit>
                </axis>
            </joint>

            <!-- <link name='left_gripper'>
                <pose relative_to="arm2">0.3 0.05 0 0 0 0.785</pose> <!--angles are in radian-->
                <inertial>
                    <mass>2</mass>
                    <inertia>
                        <ixx>0.145833</ixx>
                        <ixy>0</ixy>
                        <ixz>0</ixz>
                        <iyy>0.145833</iyy>
                        <iyz>0</iyz>
                        <izz>0.125</izz>
                    </inertia>
                </inertial>
                <visual name='visual'>
                        <geometry>
                            <mesh>
                                <uri>file://STL_Files/Left_gripper.stl</uri>
                                <scale> 0.03 0.03 0.03 </scale>
                            </mesh>
                            
                        </geometry>
                    <material>
                        <ambient>1 1 1 1</ambient>
                        <diffuse>1 1 1 1</diffuse>
                        <specular>1 1 1 1</specular>
                    </material>
                </visual>
                <collision name='collision'>
                    <geometry>
                        <box>
                            <size>0.3 0.02 0.02</size>
                        </box>
                    </geometry>
                </collision>
            </link>

            <joint name='left_gripper_joint' type='revolute'> 
                <!-- <pose relative_to="arm2">0.15 0 0 0 0 0</pose> -->
                <parent>arm2</parent>
                <child>left_gripper</child>
                <axis>
                    <xyz expressed_in='__model__'>0 1 0</xyz> 
                    <limit>
                        <lower>-1.57</lower>    
                        <upper>1.57</upper>
                    </limit>
                </axis>
            </joint>

            <link name='right_gripper'>
                <pose relative_to="arm2">0.3 -0.05 0 0 0 -0.785</pose> <!--angles are in radian-->
                <inertial>
                    <mass>2</mass>
                    <inertia>
                        <ixx>0.145833</ixx>
                        <ixy>0</ixy>
                        <ixz>0</ixz>
                        <iyy>0.145833</iyy>
                        <iyz>0</iyz>
                        <izz>0.125</izz>
                    </inertia>
                </inertial>
                <visual name='visual'>
                        <geometry>
                            <mesh>
                                <uri>file://STL_Files/Right_gripper.stl</uri>
                                <scale> 0.03 0.03 0.03 </scale>
                            </mesh> 
                        </geometry>
                    <material>
                        <ambient>1 1 1 1</ambient>
                        <diffuse>1 1 1 1</diffuse>
                        <specular>1 1 1 1</specular>
                    </material>
                </visual>
                <collision name='collision'>
                    <geometry>
                        <box>
                            <size>0.3 0.02 0.02</size>
                        </box>
                    </geometry>
                </collision>
            </link>

            <joint name='right_gripper_joint' type='revolute'> 
                <!-- <pose relative_to="arm2">0.15 0 0 0 0 0</pose> -->
                <parent>arm2</parent>
                <child>right_gripper</child>
                <axis>
                    <xyz expressed_in='__model__'>0 1 0</xyz> 
                    <limit>
                        <lower>-1.57</lower>    
                        <upper>1.57</upper>
                    </limit>
                </axis>
            </joint> -->


            <!-- <plugin
                filename="libignition-gazebo-diff-drive-system.so"
                name="ignition::gazebo::systems::DiffDrive">
                <left_joint>left_wheel_back_joint</left_joint>
                <right_joint>right_wheel_back_joint</right_joint>
                <wheel_separation>0.5</wheel_separation>
                <wheel_radius>0.1</wheel_radius>
                <odom_publish_frequency>1</odom_publish_frequency>
                <topic>cmd_vel</topic>
            </plugin>

            <plugin
                filename="libignition-gazebo-diff-drive-system.so"
                name="ignition::gazebo::systems::DiffDrive">
                <left_joint>left_wheel_front_joint</left_joint>
                <right_joint>right_wheel_front_joint</right_joint>
                <wheel_separation>0.5</wheel_separation>
                <wheel_radius>0.1</wheel_radius>
                <odom_publish_frequency>1</odom_publish_frequency>
                <topic>cmd_vel</topic>
            </plugin> -->

            <plugin
                filename="ignition-gazebo-diff-drive-system"
                name="ignition::gazebo::systems::DiffDrive">
                <left_joint>left_wheel_front_joint</left_joint>
                <right_joint>right_wheel_front_joint</right_joint>
                <wheel_separation>0.5</wheel_separation>
                <wheel_radius>0.1</wheel_radius>
                <odom_publish_frequency>1</odom_publish_frequency>
                <max_linear_acceleration>1</max_linear_acceleration>
                <min_linear_acceleration>-1</min_linear_acceleration>
                <max_angular_acceleration>2</max_angular_acceleration>
                <min_angular_acceleration>-2</min_angular_acceleration>
                <max_linear_velocity>0.5</max_linear_velocity>
                <min_linear_velocity>-0.5</min_linear_velocity>
                <max_angular_velocity>1</max_angular_velocity>
                <min_angular_velocity>-1</min_angular_velocity>
            </plugin>

            <plugin
                filename="ignition-gazebo-diff-drive-system"
                name="ignition::gazebo::systems::DiffDrive">
                <left_joint>left_wheel_back_joint</left_joint>
                <right_joint>right_wheel_back_joint</right_joint>
                <wheel_separation>0.5</wheel_separation>
                <wheel_radius>0.1</wheel_radius>
                <odom_publish_frequency>1</odom_publish_frequency>
                <max_linear_acceleration>1</max_linear_acceleration>
                <min_linear_acceleration>-1</min_linear_acceleration>
                <max_angular_acceleration>2</max_angular_acceleration>
                <min_angular_acceleration>-2</min_angular_acceleration>
                <max_linear_velocity>0.5</max_linear_velocity>
                <min_linear_velocity>-0.5</min_linear_velocity>
                <max_angular_velocity>1</max_angular_velocity>
                <min_angular_velocity>-1</min_angular_velocity>
            </plugin>

            <!-- <plugin
                filename="libignition-gazebo-diff-drive-system.so"
                name="ignition::gazebo::systems::DiffDrive">
                <left_joint>left_gripper_joint</left_joint>
                <right_joint>right_gripper_joint</right_joint>
                <wheel_separation>0.5</wheel_separation>
                <wheel_radius>0.1</wheel_radius>
                <odom_publish_frequency>1</odom_publish_frequency>
                <topic>cmd_vel</topic>
            </plugin> -->


            <!-- <plugin name="gazebo_ros_control" filename="libgazebo_ros_control.so">
                <robotNamespace>/</robotNamespace>
            </plugin> -->

                <!-- <plugin name="skid_steer_drive_controller" filename="libgazebo_ros_skid_steer_drive.so">
                    <updateRate>100.0</updateRate>
                    <robotNamespace>/</robotNamespace>
                    <leftFrontJoint>left_wheel_front_joint</leftFrontJoint>
                    <rightFrontJoint>right_wheel_front_joint</rightFrontJoint>
                    <leftRearJoint>left_wheel_back_joint</leftRearJoint>
                    <rightRearJoint>right_wheel_back_joint</rightRearJoint>
                    <wheelSeparation>0.5</wheelSeparation>
                    <wheelDiameter>0.1</wheelDiameter>
                    <robotBaseFrame>chassis</robotBaseFrame>
                    <torque>1000</torque>
                    <topicName>cmd_vel</topicName>
                    <broadcastTF>false</broadcastTF>
                </plugin> -->

  
        </model>
</sdf>
